Workbook

Sheet Fornecedores
A1: codigo contas | B1: nome fornecedores
A2: 505 | B2: FORNECEDOR PARA NOTAS CANCELADAS
A3: 506 | B3: FORNECEDOR MODELO
A4: 512 | B4: MUNDO DOS FERROS DIST. DE FERROS E ACO LTDA
A5: 514 | B5: Nova Era Mineracao Ltda
A6: 516 | B6: COMERCIAL INSTALADORA JODE LTDA- EPP -63-3215-1155
A7: 519 | B7: ENCANEL COM. DE MAT. DE CONST. LTDA
A8: 520 | B8: RENACOR COM. DE TINTAS LTDA (TAQUARALTO)
A9: 522 | B9: HILTON GANDRA DE ARRUDA E FILHOS LTDA - EPP
A10: 524 | B10: ANTONIO PEREIRA MARTINS NETO EPP
A11: 526 | B11: FERPAM COM. DE FERRAMENTAS PARAFUSOS E MAQUINAS LTDA
A12: 528 | B12: FERROTEC DISTRIBUIDORA DE FERRO E ACO LTDA.
A13: 530 | B13: MINAS GERAIS COMERCIO DE MADEIRAS LTDA
... A757: 2350 | B757: HOSPITAL DE OLHOS DO TOCANTINS LTDA

Sheet Lançamentos
A5: Data | C5: Débito | D5: Crédito | E5: Valor | G5: Débito-Crédito | I5: Histórico | N5: fornecedores
A6: 46239 | C6: 5 | D6: 467 | E6: 352.83 | G6: 0 | J6: DEVOLUÇÃO DE COMPRAS | N6: =IFERROR(VLOOKUP(D6, Fornecedores!A:B, 2, FALSE), "")
A7: 46239 | D7: 5 | E7: 349.68 | G7: 0 | J7: COMPRAS DE MERCADORIAS NESTA DATA | N7: =IFERROR(VLOOKUP(D7, Fornecedores!A:B, 2, FALSE), "")
A8: 46239 | C8: 1021 | D8: 5 | E8: 146 | G8: 0 | J8: COMPRAS DE MERCADORIAS NESTA DATA | N8: =IFERROR(VLOOKUP(C8, Fornecedores!A:B, 2, FALSE), "")
A9: 46239 | C9: 1021 | D9: 5 | E9: 433 | G9: 0 | J9: COMPRAS DE MERCADORIAS NESTA DATA | N9: =IFERROR(VLOOKUP(C9, Fornecedores!A:B, 2, FALSE), "")
A10: 46239 | C10: 1021 | D10: 5 | E10: 203.5 | G10: 0 | J10: COMPRAS DE MERCADORIAS NESTA DATA | N10: =IFERROR(VLOOKUP(C10, Fornecedores!A:B, 2, FALSE), "")
A11: 46239 | C11: 913 | D11: 5 | E11: 450.19 | G11: 0 | J11: COMPRAS DE MERCADORIAS NESTA DATA | N11: =IFERROR(VLOOKUP(C11, Fornecedores!A:B, 2, FALSE), "")
A12: 46239 | C12: 1021 | D12: 5 | E12: 4493.2 | G12: 0 | J12: COMPRAS DE MERCADORIAS NESTA DATA | N12: =IFERROR(VLOOKUP(C12, Fornecedores!A:B, 2, FALSE), "")
A13: 46239 | C13: 1021 | D13: 5 | E13: 18 | G13: 0 | J13: COMPRAS DE MERCADORIAS NESTA DATA | N13: =IFERROR(VLOOKUP(C13, Fornecedores!A:B, 2, FALSE), "")
A14: 46239 | C14: 1021 | D14: 5 | E14: 94.91 | G14: 0 | J14: COMPRAS DE MERCADORIAS NESTA DATA | N14: =IFERROR(VLOOKUP(C14, Fornecedores!A:B, 2, FALSE), "")
A15: 46239 | C15: 1021 | D15: 5 | E15: 22.09 | G15: 0 | J15: COMPRAS DE MERCADORIAS NESTA DATA | N15: =IFERROR(VLOOKUP(C15, Fornecedores!A:B, 2, FALSE), "")
A16: 46239 | D16: 5 | E16: 13800 | G16: 0 | J16: COMPRAS DE MERCADORIAS NESTA DATA | N16: =IFERROR(VLOOKUP(D16, Fornecedores!A:B, 2, FALSE), "")
A17: 46239 | D17: 5 | E17: 480 | G17: 0 | J17: COMPRAS DE MERCADORIAS NESTA DATA | N17: =IFERROR(VLOOKUP(D17, Fornecedores!A:B, 2, FALSE), "")
A18: 46239 | D18: 5 | E18: 119.76 | G18: 0 | J18: COMPRAS DE MERCADORIAS NESTA DATA | N18: =IFERROR(VLOOKUP(D18, Fornecedores!A:B, 2, FALSE), "")
A19: 46239 | D19: 5 | E19: 23 | G19: 0 | J19: COMPRAS DE MERCADORIAS NESTA DATA | N19: =IFERROR(VLOOKUP(D19, Fornecedores!A:B, 2, FALSE), "")
A20: 46239 | D20: 5 | E20: 126 | G20: 0 | J20: COMPRAS DE MERCADORIAS NESTA DATA | N20: =IFERROR(VLOOKUP(D20, Fornecedores!A:B, 2, FALSE), "")
A21: 46239 | C21: 2249 | D21: 514 | E21: 1690 | G21: 0 | J21: COMPRAS DE MERCADORIAS NESTA DATA | N21: =IFERROR(VLOOKUP(D21, Fornecedores!A:B, 2, FALSE), "") -> Nova Era Mineracao Ltda
A22: 46239 | C22: 1647 | D22: 519 | E22: 276.44 | G22: 0 | J22: COMPRAS DE MERCADORIAS NESTA DATA | N22: =IFERROR(VLOOKUP(D22, Fornecedores!A:B, 2, FALSE), "") -> ENCANEL COM. DE MAT. DE CONST. LTDA
A23: 46239 | C23: 926 | D23: 520 | E23: 1723.63 | G23: 0 | J23: COMPRAS DE MERCADORIAS NESTA DATA | N23: =IFERROR(VLOOKUP(D23, Fornecedores!A:B, 2, FALSE), "") -> RENACOR COM. DE TINTAS LTDA (TAQUARALTO)
A24: 46239 | C24: 926 | D24: 520 | E24: 35196 | G24: 0 | J24: COMPRAS DE MERCADORIAS NESTA DATA | N24: =IFERROR(VLOOKUP(D24, Fornecedores!A:B, 2, FALSE), "") -> RENACOR COM. DE TINTAS LTDA (TAQUARALTO)
A25: 46239 | C25: 917 | D25: 520 | E25: 128 | G25: 0 | J25: COMPRAS DE MERCADORIAS NESTA DATA | N25: =IFERROR(VLOOKUP(D25, Fornecedores!A:B, 2, FALSE), "") -> RENACOR COM. DE TINTAS LTDA (TAQUARALTO)
A26: 46239 | C26: 916 | D26: 520 | E26: 482.82 | G26: 0 | J26: COMPRAS DE MERCADORIAS NESTA DATA | N26: =IFERROR(VLOOKUP(D26, Fornecedores!A:B, 2, FALSE), "") -> RENACOR COM. DE TINTAS LTDA (TAQUARALTO)
A27: 46239 | C27: 1027 | D27: 522 | E27: 231 | G27: 0 | J27: COMPRAS DE MERCADORIAS NESTA DATA | N27: =IFERROR(VLOOKUP(D27, Fornecedores!A:B, 2, FALSE), "") -> HILTON GANDRA DE ARRUDA E FILHOS LTDA - EPP
A28: 46239 | C28: 928 | D28: 526 | E28: 590.14 | G28: 0 | J28: COMPRAS DE MERCADORIAS NESTA DATA | N28: =IFERROR(VLOOKUP(D28, Fornecedores!A:B, 2, FALSE), "") -> FERPAM COM. DE FERRAMENTAS PARAFUSOS E MAQUINAS LTDA
A29: 46239 | C29: 2125 | D29: 1295 | E29: 22585.7 | G29: 0 | J29: COMPRAS DE MERCADORIAS NESTA DATA | N29: =IFERROR(VLOOKUP(D29, Fornecedores!A:B, 2, FALSE), "") -> DIVIPLACAS COMERCIO E SERVICOS DE DIVISORIAS LTDA
A30: 46239 | C30: 2125 | D30: 1295 | E30: 541.4 | G30: 0 | J30: COMPRAS DE MERCADORIAS NESTA DATA | N30: =IFERROR(VLOOKUP(D30, Fornecedores!A:B, 2, FALSE), "") -> DIVIPLACAS COMERCIO E SERVICOS DE DIVISORIAS LTDA
A31: 46239 | C31: 1185 | D31: 1363 | E31: 47152.81 | G31: 0 | J31: COMPRAS DE MERCADORIAS NESTA DATA | N31: =IFERROR(VLOOKUP(D31, Fornecedores!A:B, 2, FALSE), "") -> LOCGO PALMAS LOCADORA DE EQUIPAMENTOS PARA CONSTRUCAO LTDA
A32: 46239 | C32: 1185 | D32: 1363 | E32: 37500 | G32: 0 | J32: COMPRAS DE MERCADORIAS NESTA DATA | N32: =IFERROR(VLOOKUP(D32, Fornecedores!A:B, 2, FALSE), "") -> LOCGO PALMAS LOCADORA DE EQUIPAMENTOS PARA CONSTRUCAO LTDA
... A44: 46239 | C44: 1025 | D44: 2170 | E44: 240 | G44: 0 | J44: COMPRAS DE MERCADORIAS NESTA DATA | N44: =IFERROR(VLOOKUP(D44, Fornecedores!A:B, 2, FALSE), "") -> 53595751 IAN BRUNO DA CUNHA ARRUDA
A45: 46240 | C45: 1021 | D45: 5 | E45: 26.91 | G45: 0 | J45: COMPRAS DE MERCADORIAS NESTA DATA | N45: =IFERROR(VLOOKUP(C45, Fornecedores!A:B, 2, FALSE), "")
A46: 46240 | C46: 1021 | D46: 5 | E46: 18 | G46: 0 | J46: COMPRAS DE MERCADORIAS NESTA DATA | N46: =IFERROR(VLOOKUP(C46, Fornecedores!A:B, 2, FALSE), "")
A47: 46240 | C47: 1021 | D47: 5 | E47: 20.95 | G47: 0 | J47: COMPRAS DE MERCADORIAS NESTA DATA | N47: =IFERROR(VLOOKUP(C47, Fornecedores!A:B, 2, FALSE), "")
A48: 46240 | C48: 1021 | D48: 5 | E48: 3.99 | G48: 0 | J48: COMPRAS DE MERCADORIAS NESTA DATA | N48: =IFERROR(VLOOKUP(C48, Fornecedores!A:B, 2, FALSE), "")
A49: 46240 | C49: 1021 | D49: 5 | E49: 4 | G49: 0 | J49: COMPRAS DE MERCADORIAS NESTA DATA | N49: =IFERROR(VLOOKUP(C49, Fornecedores!A:B, 2, FALSE), "")
A50: 46240 | C50: 1021 | D50: 5 | E50: 118 | G50: 0 | J50: COMPRAS DE MERCADORIAS NESTA DATA | N50: =IFERROR(VLOOKUP(C50, Fornecedores!A:B, 2, FALSE), "")
A51: 46240 | C51: 963 | D51: 5 | E51: 1221.1 | G51: 0 | J51: COMPRAS DE MERCADORIAS NESTA DATA | N51: =IFERROR(VLOOKUP(C51, Fornecedores!A:B, 2, FALSE), "")
A52: 46240 | C52: 2050 | D52: 5 | E52: 125.31 | G52: 0 | J52: COMPRAS DE MERCADORIAS NESTA DATA | N52: =IFERROR(VLOOKUP(C52, Fornecedores!A:B, 2, FALSE), "")
A53: 46240 | C53: 1021 | D53: 5 | E53: 20.88 | G53: 0 | J53: COMPRAS DE MERCADORIAS NESTA DATA | N53: =IFERROR(VLOOKUP(C53, Fornecedores!A:B, 2, FALSE), "")
A54: 46240 | C54: 1021 | D54: 5 | E54: 1960 | G54: 0 | J54: COMPRAS DE MERCADORIAS NESTA DATA | N54: =IFERROR(VLOOKUP(C54, Fornecedores!A:B, 2, FALSE), "")
A55: 46240 | D55: 5 | E55: 7087.5 | G55: 0 | J55: COMPRAS DE MERCADORIAS NESTA DATA | N55: =IFERROR(VLOOKUP(D55, Fornecedores!A:B, 2, FALSE), "")
...
